Workbook

Sheet Indice
A1: ACZO · RADAR DE MERCADOS — OMIE (pasado) + OMIP (futuro) · 2.0TD y 3.0/6.1TD
C3: PARA QUÉ SIRVE
C4: Panel de seguimiento de mercado para el equipo: el retrovisor (spot OMIE desde 2023), el mes en curso (diario) y el parabrisas (futuros OMIP). Sin cliente cargado: es la foto del mercado. Los estudios de cliente viven en los otros Excel.
C6: HOJAS
B7: OMIE_20 | C7: Spot mensual por periodo P1/P2/P3 (calendario 2.0TD) + precios diarios del mes en curso + año en curso. Verde/rojo contra el umbral que fijes.
B8: OMIE_6P | C8: Spot mensual por periodo P1…P6 (calendario 3.0TD/6.1TD, con temporadas). Cada mes solo cotiza los periodos de SU temporada, más P6.
B9: OMIP | C9: Futuros: curva mensual, trimestral y anual + forward 12 meses + ventana de fijación. Con consulta automática o manual (celdas amarillas).
B10: PQ_* | C10: Zonas Power Query OPCIONALES (Guia_PowerQuery_Mercados.md). Con el actualizador automático instalado NO hacen falta: los datos llegan ya escritos.
C12: ACTUALIZACIÓN: el actualizador automático (carpeta _automatizacion) reescribe este archivo cada día a las 21:15 con OMIE (incluido el precio de MAÑANA, publicado ~13:00) y la curva OMIP del día. Tú solo abres el Excel. Si el Mac estaba apagado a esa hora, se ejecuta al encenderlo. No dejes el archivo abierto permanentemente: al estar abierto, la actualización de ese día no puede escribirse.

Sheet OMIE_20
A1: OMIE — SPOT 2.0TD: histórico mensual + mes en curso
A2: Izquierda: spot medio mensual por periodo 2.0TD (2023 → hoy; las filas hasta dic-2027 se rellenan solas con Power Query al cerrar cada mes). Centro: precios diarios del mes en curso (mín/media/máx cuartohorarios). Derecha: año en curso. VERDE = mes por debajo del umbral · ROJO = por encima. Fuente: omie.es marginalpdbc (validado 0,0% vs informe oficial OMIE).
H3: Mes del panel → | I3: =IFERROR(DATE(YEAR(MAX(PQ_Diario!A:A)),MONTH(MAX(PQ_Diario!A:A)),1),DATE(2026,8,1))
A4: UMBRAL de color (€/MWh) — p.ej. mejor fijo del catálogo o quiebre del cliente → | F4: 110 | H4: MES EN CURSO — precios diarios (€/MWh, cuartohorario) | Q4: AÑO 2026 (€/MWh)
A5: Mes | B5: P1 punta | C5: P2 llano | D5: P3 valle | E5: Media (€/kWh) | F5: Media (€/MWh) | H5: Día | I5: Mínimo | J5: Media | K5: Máximo | Q5: Mes | R5: Media
A6: 44927 | B6: =IFERROR(VLOOKUP($A6,PQ_Mensual!$A:$D,2,0),S6) | C6: =IFERROR(VLOOKUP($A6,PQ_Mensual!$A:$D,3,0),T6) | D6: =IFERROR(VLOOKUP($A6,PQ_Mensual!$A:$D,4,0),U6) | E6: =IF(COUNT(B6:D6)=0,"",AVERAGE(B6:D6)) | F6: =IF(E6="","",E6*1000) | H6: =IF(1>DAY(EOMONTH($I$3,0)),"",DATE(YEAR($I$3),MONTH($I$3),1)) | I6: =IF($H6="","",IFERROR(VLOOKUP($H6,PQ_Diario!$A:$D,2,0),V6)) | J6: =IF($H6="","",IFERROR(VLOOKUP($H6,PQ_Diario!$A:$D,3,0),W6)) | K6: =IF($H6="","",IFERROR(VLOOKUP($H6,PQ_Diario!$A:$D,4,0),X6)) | Q6: =A42 | R6: =IF(F42="","",F42) | S6: 0.10304 | T6: 0.08528 | U6: 0.04928 | V6: 0.29 | W6: 111.68 | X6: 198.69
A7: 44958 | B7: =IFERROR(VLOOKUP($A7,PQ_Mensual!$A:$D,2,0),S7) | C7: =IFERROR(VLOOKUP($A7,PQ_Mensual!$A:$D,3,0),T7) | D7: =IFERROR(VLOOKUP($A7,PQ_Mensual!$A:$D,4,0),U7) | E7: =IF(COUNT(B7:D7)=0,"",AVERAGE(B7:D7)) | F7: =IF(E7="","",E7*1000) | H7: =IF(2>DAY(EOMONTH($I$3,0)),"",DATE(YEAR($I$3),MONTH($I$3),2)) | I7: =IF($H7="","",IFERROR(VLOOKUP($H7,PQ_Diario!$A:$D,2,0),V7)) | J7: =IF($H7="","",IFERROR(VLOOKUP($H7,PQ_Diario!$A:$D,3,0),W7)) | K7: =IF($H7="","",IFERROR(VLOOKUP($H7,PQ_Diario!$A:$D,4,0),X7)) | Q7: =A43 | R7: =IF(F43="","",F43) | S7: 0.14863 | T7: 0.14111 | U7: 0.12311 | V7: -0.3 | W7: 106.2 | X7: 210.3
A8: 44986 | B8: =IFERROR(VLOOKUP($A8,PQ_Mensual!$A:$D,2,0),S8) | C8: =IFERROR(VLOOKUP($A8,PQ_Mensual!$A:$D,3,0),T8) | D8: =IFERROR(VLOOKUP($A8,PQ_Mensual!$A:$D,4,0),U8) | E8: =IF(COUNT(B8:D8)=0,"",AVERAGE(B8:D8)) | F8: =IF(E8="","",E8*1000) | H8: =IF(3>DAY(EOMONTH($I$3,0)),"",DATE(YEAR($I$3),MONTH($I$3),3)) | I8: =IF($H8="","",IFERROR(VLOOKUP($H8,PQ_Diario!$A:$D,2,0),V8)) | J8: =IF($H8="","",IFERROR(VLOOKUP($H8,PQ_Diario!$A:$D,3,0),W8)) | K8: =IF($H8="","",IFERROR(VLOOKUP($H8,PQ_Diario!$A:$D,4,0),X8)) | Q8: =A44 | R8: =IF(F44="","",F44) | S8: 0.09548 | T8: 0.08709 | U8: 0.08814 | V8: 75 | W8: 151.87 | X8: 222.69
A9: 45017 | B9: =IFERROR(VLOOKUP($A9,PQ_Mensual!$A:$D,2,0),S9) | C9: =IFERROR(VLOOKUP($A9,PQ_Mensual!$A:$D,3,0),T9) | D9: =IFERROR(VLOOKUP($A9,PQ_Mensual!$A:$D,4,0),U9) | E9: =IF(COUNT(B9:D9)=0,"",AVERAGE(B9:D9)) | F9: =IF(E9="","",E9*1000) | H9: =IF(4>DAY(EOMONTH($I$3,0)),"",DATE(YEAR($I$3),MONTH($I$3),4)) | I9: =IF($H9="","",IFERROR(VLOOKUP($H9,PQ_Diario!$A:$D,2,0),V9)) | J9: =IF($H9="","",IFERROR(VLOOKUP($H9,PQ_Diario!$A:$D,3,0),W9)) | K9: =IF($H9="","",IFERROR(VLOOKUP($H9,PQ_Diario!$A:$D,4,0),X9)) | Q9: =A45 | R9: =IF(F45="","",F45) | S9: 0.08031 | T9: 0.07497 | U9: 0.07088 | V9: 69 | W9: 146.37 | X9: 212.52
A10: 45047 | B10: =IFERROR(VLOOKUP($A10,PQ_Mensual!$A:$D,2,0),S10) | C10: =IFERROR(VLOOKUP($A10,PQ_Mensual!$A:$D,3,0),T10) | D10: =IFERROR(VLOOKUP($A10,PQ_Mensual!$A:$D,4,0),U10) | E10: =IF(COUNT(B10:D10)=0,"",AVERAGE(B10:D10)) | F10: =IF(E10="","",E10*1000) | H10: =IF(5>DAY(EOMONTH($I$3,0)),"",DATE(YEAR($I$3),MONTH($I$3),5)) | I10: =IF($H10="","",IFERROR(VLOOKUP($H10,PQ_Diario!$A:$D,2,0),V10)) | J10: =IF($H10="","",IFERROR(VLOOKUP($H10,PQ_Diario!$A:$D,3,0),W10)) | K10: =IF($H10="","",IFERROR(VLOOKUP($H10,PQ_Diario!$A:$D,4,0),X10)) | Q10: =A46 | R10: =IF(F46="","",F46) | S10: 0.07675 | T10: 0.07446 | U10: 0.07295 | V10: 4 | W10: 118.92 | X10: 199.47
A11: 45078 | B11: =IFERROR(VLOOKUP($A11,PQ_Mensual!$A:$D,2,0),S11) | C11: =IFERROR(VLOOKUP($A11,PQ_Mensual!$A:$D,3,0),T11) | D11: =IFERROR(VLOOKUP($A11,PQ_Mensual!$A:$D,4,0),U11) | E11: =IF(COUNT(B11:D11)=0,"",AVERAGE(B11:D11)) | F11: =IF(E11="","",E11*1000) | H11: =IF(6>DAY(EOMONTH($I$3,0)),"",DATE(YEAR($I$3),MONTH($I$3),6)) | I11: =IF($H11="","",IFERROR(VLOOKUP($H11,PQ_Diario!$A:$D,2,0),V11)) | J11: =IF($H11="","",IFERROR(VLOOKUP($H11,PQ_Diario!$A:$D,3,0),W11)) | K11: =IF($H11="","",IFERROR(VLOOKUP($H11,PQ_Diario!$A:$D,4,0),X11)) | Q11: =A47 | R11: =IF(F47="","",F47) | S11: 0.09821 | T11: 0.09727 | U11: 0.08851 | V11: 1.5 | W11: 109.51 | X11: 209.61
A12: 45108 | B12: =IFERROR(VLOOKUP($A12,PQ_Mensual!$A:$D,2,0),S12) | C12: =IFERROR(VLOOKUP($A12,PQ_Mensual!$A:$D,3,0),T12) | D12: =IFERROR(VLOOKUP($A12,PQ_Mensual!$A:$D,4,0),U12) | E12: =IF(COUNT(B12:D12)=0,"",AVERAGE(B12:D12)) | F12: =IF(E12="","",E12*1000) | H12: =IF(7>DAY(EOMONTH($I$3,0)),"",DATE(YEAR($I$3),MONTH($I$3),7)) | I12: =IF($H12="","",IFERROR(VLOOKUP($H12,PQ_Diario!$A:$D,2,0),V12)) | J12: =IF($H12="","",IFERROR(VLOOKUP($H12,PQ_Diario!$A:$D,3,0),W12)) | K12: =IF($H12="","",IFERROR(VLOOKUP($H12,PQ_Diario!$A:$D,4,0),X12)) | Q12: =A48 | R12: =IF(F48="","",F48) | S12: 0.09831 | T12: 0.09756 | U12: 0.08432 | V12: 5 | W12: 119.03 | X12: 220
A13: 45139 | B13: =IFERROR(VLOOKUP($A13,PQ_Mensual!$A:$D,2,0),S13) | C13: =IFERROR(VLOOKUP($A13,PQ_Mensual!$A:$D,3,0),T13) | D13: =IFERROR(VLOOKUP($A13,PQ_Mensual!$A:$D,4,0),U13) | E13: =IF(COUNT(B13:D13)=0,"",AVERAGE(B13:D13)) | F13: =IF(E13="","",E13*1000) | H13: =IF(8>DAY(EOMONTH($I$3,0)),"",DATE(YEAR($I$3),MONTH($I$3),8)) | I13: =IF($H13="","",IFERROR(VLOOKUP($H13,PQ_Diario!$A:$D,2,0),V13)) | J13: =IF($H13="","",IFERROR(VLOOKUP($H13,PQ_Diario!$A:$D,3,0),W13)) | K13: =IF($H13="","",IFERROR(VLOOKUP($H13,PQ_Diario!$A:$D,4,0),X13)) | Q13: =A49 | R13: =IF(F49="","",F49) | S13: 0.10144 | T13: 0.0983 | U13: 0.09261 | V13: 0 | W13: 108.61 | X13: 191.01
A14: 45170 | B14: =IFERROR(VLOOKUP($A14,PQ_Mensual!$A:$D,2,0),S14) | C14: =IFERROR(VLOOKUP($A14,PQ_Mensual!$A:$D,3,0),T14) | D14: =IFERROR(VLOOKUP($A14,PQ_Mensual!$A:$D,4,0),U14) | E14: =IF(COUNT(B14:D14)=0,"",AVERAGE(B14:D14)) | F14: =IF(E14="","",E14*1000) | H14: =IF(9>DAY(EOMONTH($I$3,0)),"",DATE(YEAR($I$3),MONTH($I$3),9)) | I14: =IF($H14="","",IFERROR(VLOOKUP($H14,PQ_Diario!$A:$D,2,0),V14)) | J14: =IF($H14="","",IFERROR(VLOOKUP($H14,PQ_Diario!$A:$D,3,0),W14)) | K14: =IF($H14="","",IFERROR(VLOOKUP($H14,PQ_Diario!$A:$D,4,0),X14)) | Q14: =A50 | R14: =IF(F50="","",F50) | S14: 0.11233 | T14: 0.10545 | U14: 0.09848 | V14: -0.11 | W14: 94.39 | X14: 175.73
A15: 45200 | B15: =IFERROR(VLOOKUP($A15,PQ_Mensual!$A:$D,2,0),S15) | C15: =IFERROR(VLOOKUP($A15,PQ_Mensual!$A:$D,3,0),T15) | D15: =IFERROR(VLOOKUP($A15,PQ_Mensual!$A:$D,4,0),U15) | E15: =IF(COUNT(B15:D15)=0,"",AVERAGE(B15:D15)) | F15: =IF(E15="","",E15*1000) | H15: =IF(10>DAY(EOMONTH($I$3,0)),"",DATE(YEAR($I$3),MONTH($I$3),10)) | I15: =IF($H15="","",IFERROR(VLOOKUP($H15,PQ_Diario!$A:$D,2,0),V15)) | J15: =IF($H15="","",IFERROR(VLOOKUP($H15,PQ_Diario!$A:$D,3,0),W15)) | K15: =IF($H15="","",IFERROR(VLOOKUP($H15,PQ_Diario!$A:$D,4,0),X15)) | Q15: =A51 | R15: =IF(F51="","",F51) | S15: 0.0998 | T15: 0.09149 | U15: 0.08542 | V15: 21 | W15: 126.76 | X15: 233.76
A16: 45231 | B16: =IFERROR(VLOOKUP($A16,PQ_Mensual!$A:$D,2,0),S16) | C16: =IFERROR(VLOOKUP($A16,PQ_Mensual!$A:$D,3,0),T16) | D16: =IFERROR(VLOOKUP($A16,PQ_Mensual!$A:$D,4,0),U16) | E16: =IF(COUNT(B16:D16)=0,"",AVERAGE(B16:D16)) | F16: =IF(E16="","",E16*1000) | H16: =IF(11>DAY(EOMONTH($I$3,0)),"",DATE(YEAR($I$3),MONTH($I$3),11)) | I16: =IF($H16="","",IFERROR(VLOOKUP($H16,PQ_Diario!$A:$D,2,0),V16)) | J16: =IF($H16="","",IFERROR(VLOOKUP($H16,PQ_Diario!$A:$D,3,0),W16)) | K16: =IF($H16="","",IFERROR(VLOOKUP($H16,PQ_Diario!$A:$D,4,0),X16)) | Q16: =A52 | R16: =IF(F52="","",F52) | S16: 0.08009 | T16: 0.07352 | U16: 0.05176 | V16: 12.14 | W16: 128.85 | X16: 235.51
A17: 45261 | B17: =IFERROR(VLOOKUP($A17,PQ_Mensual!$A:$D,2,0),S17) | C17: =IFERROR(VLOOKUP($A17,PQ_Mensual!$A:$D,3,0),T17) | D17: =IFERROR(VLOOKUP($A17,PQ_Mensual!$A:$D,4,0),U17) | E17: =IF(COUNT(B17:D17)=0,"",AVERAGE(B17:D17)) | F17: =IF(E17="","",E17*1000) | H17: =IF(12>DAY(EOMONTH($I$3,0)),"",DATE(YEAR($I$3),MONTH($I$3),12)) | I17: =IF($H17="","",IFERROR(VLOOKUP($H17,PQ_Diario!$A:$D,2,0),V17)) | J17: =IF($H17="","",IFERROR(VLOOKUP($H17,PQ_Diario!$A:$D,3,0),W17)) | K17: =IF($H17="","",IFERROR(VLOOKUP($H17,PQ_Diario!$A:$D,4,0),X17)) | Q17: =A53 | R17: =IF(F53="","",F53) | S17: 0.08818 | T17: 0.08316 | U17: 0.06365 | V17: 12 | W17: 135.31 | X17: 250
A18: 45292 | B18: =IFERROR(VLOOKUP($A18,PQ_Mensual!$A:$D,2,0),S18) | C18: =IFERROR(VLOOKUP($A18,PQ_Mensual!$A:$D,3,0),T18) | D18: =IFERROR(VLOOKUP($A18,PQ_Mensual!$A:$D,4,0),U18) | E18: =IF(COUNT(B18:D18)=0,"",AVERAGE(B18:D18)) | F18: =IF(E18="","",E18*1000) | H18: =IF(13>DAY(EOMONTH($I$3,0)),"",DATE(YEAR($I$3),MONTH($I$3),13)) | I18: =IF($H18="","",IFERROR(VLOOKUP($H18,PQ_Diario!$A:$D,2,0),"")) | J18: =IF($H18="","",IFERROR(VLOOKUP($H18,PQ_Diario!$A:$D,3,0),"")) | K18: =IF($H18="","",IFERROR(VLOOKUP($H18,PQ_Diario!$A:$D,4,0),"")) | Q18: =$I$3 | R18: =J39 | S18: 0.08842 | T18: 0.08177 | U18: 0.06423
A19: 45323 | B19: =IFERROR(VLOOKUP($A19,PQ_Mensual!$A:$D,2,0),S19) | C19: =IFERROR(VLOOKUP($A19,PQ_Mensual!$A:$D,3,0),T19) | D19: =IFERROR(VLOOKUP($A19,PQ_Mensual!$A:$D,4,0),U19) | E19: =IF(COUNT(B19:D19)=0,"",AVERAGE(B19:D19)) | F19: =IF(E19="","",E19*1000) | H19: =IF(14>DAY(EOMONTH($I$3,0)),"",DATE(YEAR($I$3),MONTH($I$3),14)) | I19: =IF($H19="","",IFERROR(VLOOKUP($H19,PQ_Diario!$A:$D,2,0),"")) | J19: =IF($H19="","",IFERROR(VLOOKUP($H19,PQ_Diario!$A:$D,3,0),"")) | K19: =IF($H19="","",IFERROR(VLOOKUP($H19,PQ_Diario!$A:$D,4,0),"")) | S19: 0.04724 | T19: 0.04088 | U19: 0.03621
A20: 45352 | B20: =IFERROR(VLOOKUP($A20,PQ_Mensual!$A:$D,2,0),S20) | C20: =IFERROR(VLOOKUP($A20,PQ_Mensual!$A:$D,3,0),T20) | D20: =IFERROR(VLOOKUP($A20,PQ_Mensual!$A:$D,4,0),U20) | E20: =IF(COUNT(B20:D20)=0,"",AVERAGE(B20:D20)) | F20: =IF(E20="","",E20*1000) | H20: =IF(15>DAY(EOMONTH($I$3,0)),"",DATE(YEAR($I$3),MONTH($I$3),15)) | I20: =IF($H20="","",IFERROR(VLOOKUP($H20,PQ_Diario!$A:$D,2,0),"")) | J20: =IF($H20="","",IFERROR(VLOOKUP($H20,PQ_Diario!$A:$D,3,0),"")) | K20: =IF($H20="","",IFERROR(VLOOKUP($H20,PQ_Diario!$A:$D,4,0),"")) | S20: 0.03233 | T20: 0.02246 | U20: 0.01494
A21: 45383 | B21: =IFERROR(VLOOKUP($A21,PQ_Mensual!$A:$D,2,0),S21) | C21: =IFERROR(VLOOKUP($A21,PQ_Mensual!$A:$D,3,0),T21) | D21: =IFERROR(VLOOKUP($A21,PQ_Mensual!$A:$D,4,0),U21) | E21: =IF(COUNT(B21:D21)=0,"",AVERAGE(B21:D21)) | F21: =IF(E21="","",E21*1000) | H21: =IF(16>DAY(EOMONTH($I$3,0)),"",DATE(YEAR($I$3),MONTH($I$3),16)) | I21: =IF($H21="","",IFERROR(VLOOKUP($H21,PQ_Diario!$A:$D,2,0),"")) | J21: =IF($H21="","",IFERROR(VLOOKUP($H21,PQ_Diario!$A:$D,3,0),"")) | K21: =IF($H21="","",IFERROR(VLOOKUP($H21,PQ_Diario!$A:$D,4,0),"")) | S21: 0.01418 | T21: 0.0138 | U21: 0.01337
A22: 45413 | B22: =IFERROR(VLOOKUP($A22,PQ_Mensual!$A:$D,2,0),S22) | C22: =IFERROR(VLOOKUP($A22,PQ_Mensual!$A:$D,3,0),T22) | D22: =IFERROR(VLOOKUP($A22,PQ_Mensual!$A:$D,4,0),U22) | E22: =IF(COUNT(B22:D22)=0,"",AVERAGE(B22:D22)) | F22: =IF(E22="","",E22*1000) | H22: =IF(17>DAY(EOMONTH($I$3,0)),"",DATE(YEAR($I$3),MONTH($I$3),17)) | I22: =IF($H22="","",IFERROR(VLOOKUP($H22,PQ_Diario!$A:$D,2,0),"")) | J22: =IF($H22="","",IFERROR(VLOOKUP($H22,PQ_Diario!$A:$D,3,0),"")) | K22: =IF($H22="","",IFERROR(VLOOKUP($H22,PQ_Diario!$A:$D,4,0),"")) | S22: 0.02666 | T22: 0.02822 | U22: 0.03306
A23: 45444 | B23: =IFERROR(VLOOKUP($A23,PQ_Mensual!$A:$D,2,0),S23) | C23: =IFERROR(VLOOKUP($A23,PQ_Mensual!$A:$D,3,0),T23) | D23: =IFERROR(VLOOKUP($A23,PQ_Mensual!$A:$D,4,0),U23) | E23: =IF(COUNT(B23:D23)=0,"",AVERAGE(B23:D23)) | F23: =IF(E23="","",E23*1000) | H23: =IF(18>DAY(EOMONTH($I$3,0)),"",DATE(YEAR($I$3),MONTH($I$3),18)) | I23: =IF($H23="","",IFERROR(VLOOKUP($H23,PQ_Diario!$A:$D,2,0),"")) | J23: =IF($H23="","",IFERROR(VLOOKUP($H23,PQ_Diario!$A:$D,3,0),"")) | K23: =IF($H23="","",IFERROR(VLOOKUP($H23,PQ_Diario!$A:$D,4,0),"")) | S23: 0.06157 | T23: 0.06107 | U23: 0.05189
A24: 45474 | B24: =IFERROR(VLOOKUP($A24,PQ_Mensual!$A:$D,2,0),S24) | C24: =IFERROR(VLOOKUP($A24,PQ_Mensual!$A:$D,3,0),T24) | D24: =IFERROR(VLOOKUP($A24,PQ_Mensual!$A:$D,4,0),U24) | E24: =IF(COUNT(B24:D24)=0,"",AVERAGE(B24:D24)) | F24: =IF(E24="","",E24*1000) | H24: =IF(19>DAY(EOMONTH($I$3,0)),"",DATE(YEAR($I$3),MONTH($I$3),19)) | I24: =IF($H24="","",IFERROR(VLOOKUP($H24,PQ_Diario!$A:$D,2,0),"")) | J24: =IF($H24="","",IFERROR(VLOOKUP($H24,PQ_Diario!$A:$D,3,0),"")) | K24: =IF($H24="","",IFERROR(VLOOKUP($H24,PQ_Diario!$A:$D,4,0),"")) | S24: 0.07452 | T24: 0.07392 | U24: 0.07045
A25: 45505 | B25: =IFERROR(VLOOKUP($A25,PQ_Mensual!$A:$D,2,0),S25) | C25: =IFERROR(VLOOKUP($A25,PQ_Mensual!$A:$D,3,0),T25) | D25: =IFERROR(VLOOKUP($A25,PQ_Mensual!$A:$D,4,0),U25) | E25: =IF(COUNT(B25:D25)=0,"",AVERAGE(B25:D25)) | F25: =IF(E25="","",E25*1000) | H25: =IF(20>DAY(EOMONTH($I$3,0)),"",DATE(YEAR($I$3),MONTH($I$3),20)) | I25: =IF($H25="","",IFERROR(VLOOKUP($H25,PQ_Diario!$A:$D,2,0),"")) | J25: =IF($H25="","",IFERROR(VLOOKUP($H25,PQ_Diario!$A:$D,3,0),"")) | K25: =IF($H25="","",IFERROR(VLOOKUP($H25,PQ_Diario!$A:$D,4,0),"")) | S25: 0.09821 | T25: 0.09719 | U25: 0.08558
A26: 45536 | B26: =IFERROR(VLOOKUP($A26,PQ_Mensual!$A:$D,2,0),S26) | C26: =IFERROR(VLOOKUP($A26,PQ_Mensual!$A:$D,3,0),T26) | D26: =IFERROR(VLOOKUP($A26,PQ_Mensual!$A:$D,4,0),U26) | E26: =IF(COUNT(B26:D26)=0,"",AVERAGE(B26:D26)) | F26: =IF(E26="","",E26*1000) | H26: =IF(21>DAY(EOMONTH($I$3,0)),"",DATE(YEAR($I$3),MONTH($I$3),21)) | I26: =IF($H26="","",IFERROR(VLOOKUP($H26,PQ_Diario!$A:$D,2,0),"")) | J26: =IF($H26="","",IFERROR(VLOOKUP($H26,PQ_Diario!$A:$D,3,0),"")) | K26: =IF($H26="","",IFERROR(VLOOKUP($H26,PQ_Diario!$A:$D,4,0),"")) | S26: 0.07683 | T26: 0.06871 | U26: 0.0725
A27: 45566 | B27: =IFERROR(VLOOKUP($A27,PQ_Mensual!$A:$D,2,0),S27) | C27: =IFERROR(VLOOKUP($A27,PQ_Mensual!$A:$D,3,0),T27) | D27: =IFERROR(VLOOKUP($A27,PQ_Mensual!$A:$D,4,0),U27) | E27: =IF(COUNT(B27:D27)=0,"",AVERAGE(B27:D27)) | F27: =IF(E27="","",E27*1000) | H27: =IF(22>DAY(EOMONTH($I$3,0)),"",DATE(YEAR($I$3),MONTH($I$3),22)) | I27: =IF($H27="","",IFERROR(VLOOKUP($H27,PQ_Diario!$A:$D,2,0),"")) | J27: =IF($H27="","",IFERROR(VLOOKUP($H27,PQ_Diario!$A:$D,3,0),"")) | K27: =IF($H27="","",IFERROR(VLOOKUP($H27,PQ_Diario!$A:$D,4,0),"")) | S27: 0.08348 | T27: 0.07218 | U27: 0.0595
A28: 45597 | B28: =IFERROR(VLOOKUP($A28,PQ_Mensual!$A:$D,2,0),S28) | C28: =IFERROR(VLOOKUP($A28,PQ_Mensual!$A:$D,3,0),T28) | D28: =IFERROR(VLOOKUP($A28,PQ_Mensual!$A:$D,4,0),U28) | E28: =IF(COUNT(B28:D28)=0,"",AVERAGE(B28:D28)) | F28: =IF(E28="","",E28*1000) | H28: =IF(23>DAY(EOMONTH($I$3,0)),"",DATE(YEAR($I$3),MONTH($I$3),23)) | I28: =IF($H28="","",IFERROR(VLOOKUP($H28,PQ_Diario!$A:$D,2,0),"")) | J28: =IF($H28="","",IFERROR(VLOOKUP($H28,PQ_Diario!$A:$D,3,0),"")) | K28: =IF($H28="","",IFERROR(VLOOKUP($H28,PQ_Diario!$A:$D,4,0),"")) | S28: 0.11843 | T28: 0.11628 | U28: 0.09409
A29: 45627 | B29: =IFERROR(VLOOKUP($A29,PQ_Mensual!$A:$D,2,0),S29) | C29: =IFERROR(VLOOKUP($A29,PQ_Mensual!$A:$D,3,0),T29) | D29: =IFERROR(VLOOKUP($A29,PQ_Mensual!$A:$D,4,0),U29) | E29: =IF(COUNT(B29:D29)=0,"",AVERAGE(B29:D29)) | F29: =IF(E29="","",E29*1000) | H29: =IF(24>DAY(EOMONTH($I$3,0)),"",DATE(YEAR($I$3),MONTH($I$3),24)) | I29: =IF($H29="","",IFERROR(VLOOKUP($H29,PQ_Diario!$A:$D,2,0),"")) | J29: =IF($H29="","",IFERROR(VLOOKUP($H29,PQ_Diario!$A:$D,3,0),"")) | K29: =IF($H29="","",IFERROR(VLOOKUP($H29,PQ_Diario!$A:$D,4,0),"")) | S29: 0.1267 | T29: 0.12543 | U29: 0.10005
A30: 45658 | B30: =IFERROR(VLOOKUP($A30,PQ_Mensual!$A:$D,2,0),S30) | C30: =IFERROR(VLOOKUP($A30,PQ_Mensual!$A:$D,3,0),T30) | D30: =IFERROR(VLOOKUP($A30,PQ_Mensual!$A:$D,4,0),U30) | E30: =IF(COUNT(B30:D30)=0,"",AVERAGE(B30:D30)) | F30: =IF(E30="","",E30*1000) | H30: =IF(25>DAY(EOMONTH($I$3,0)),"",DATE(YEAR($I$3),MONTH($I$3),25)) | I30: =IF($H30="","",IFERROR(VLOOKUP($H30,PQ_Diario!$A:$D,2,0),"")) | J30: =IF($H30="","",IFERROR(VLOOKUP($H30,PQ_Diario!$A:$D,3,0),"")) | K30: =IF($H30="","",IFERROR(VLOOKUP($H30,PQ_Diario!$A:$D,4,0),"")) | S30: 0.11618 | T30: 0.11035 | U30: 0.08304
A31: 45689 | B31: =IFERROR(VLOOKUP($A31,PQ_Mensual!$A:$D,2,0),S31) | C31: =IFERROR(VLOOKUP($A31,PQ_Mensual!$A:$D,3,0),T31) | D31: =IFERROR(VLOOKUP($A31,PQ_Mensual!$A:$D,4,0),U31) | E31: =IF(COUNT(B31:D31)=0,"",AVERAGE(B31:D31)) | F31: =IF(E31="","",E31*1000) | H31: =IF(26>DAY(EOMONTH($I$3,0)),"",DATE(YEAR($I$3),MONTH($I$3),26)) | I31: =IF($H31="","",IFERROR(VLOOKUP($H31,PQ_Diario!$A:$D,2,0),"")) | J31: =IF($H31="","",IFERROR(VLOOKUP($H31,PQ_Diario!$A:$D,3,0),"")) | K31: =IF($H31="","",IFERROR(VLOOKUP($H31,PQ_Diario!$A:$D,4,0),"")) | S31: 0.1231 | T31: 0.10975 | U31: 0.10093
A32: 45717 | B32: =IFERROR(VLOOKUP($A32,PQ_Mensual!$A:$D,2,0),S32) | C32: =IFERROR(VLOOKUP($A32,PQ_Mensual!$A:$D,3,0),T32) | D32: =IFERROR(VLOOKUP($A32,PQ_Mensual!$A:$D,4,0),U32) | E32: =IF(COUNT(B32:D32)=0,"",AVERAGE(B32:D32)) | F32: =IF(E32="","",E32*1000) | H32: =IF(27>DAY(EOMONTH($I$3,0)),"",DATE(YEAR($I$3),MONTH($I$3),27)) | I32: =IF($H32="","",IFERROR(VLOOKUP($H32,PQ_Diario!$A:$D,2,0),"")) | J32: =IF($H32="","",IFERROR(VLOOKUP($H32,PQ_Diario!$A:$D,3,0),"")) | K32: =IF($H32="","",IFERROR(VLOOKUP($H32,PQ_Diario!$A:$D,4,0),"")) | S32: 0.07069 | T32: 0.05524 | U32: 0.04494
A33: 45748 | B33: =IFERROR(VLOOKUP($A33,PQ_Mensual!$A:$D,2,0),S33) | C33: =IFERROR(VLOOKUP($A33,PQ_Mensual!$A:$D,3,0),T33) | D33: =IFERROR(VLOOKUP($A33,PQ_Mensual!$A:$D,4,0),U33) | E33: =IF(COUNT(B33:D33)=0,"",AVERAGE(B33:D33)) | F33: =IF(E33="","",E33*1000) | H33: =IF(28>DAY(EOMONTH($I$3,0)),"",DATE(YEAR($I$3),MONTH($I$3),28)) | I33: =IF($H33="","",IFERROR(VLOOKUP($H33,PQ_Diario!$A:$D,2,0),"")) | J33: =IF($H33="","",IFERROR(VLOOKUP($H33,PQ_Diario!$A:$D,3,0),"")) | K33: =IF($H33="","",IFERROR(VLOOKUP($H33,PQ_Diario!$A:$D,4,0),"")) | S33: 0.02763 | T33: 0.02789 | U33: 0.02598
A34: 45778 | B34: =IFERROR(VLOOKUP($A34,PQ_Mensual!$A:$D,2,0),S34) | C34: =IFERROR(VLOOKUP($A34,PQ_Mensual!$A:$D,3,0),T34) | D34: =IFERROR(VLOOKUP($A34,PQ_Mensual!$A:$D,4,0),U34) | E34: =IF(COUNT(B34:D34)=0,"",AVERAGE(B34:D34)) | F34: =IF(E34="","",E34*1000) | H34: =IF(29>DAY(EOMONTH($I$3,0)),"",DATE(YEAR($I$3),MONTH($I$3),29)) | I34: =IF($H34="","",IFERROR(VLOOKUP($H34,PQ_Diario!$A:$D,2,0),"")) | J34: =IF($H34="","",IFERROR(VLOOKUP($H34,PQ_Diario!$A:$D,3,0),"")) | K34: =IF($H34="","",IFERROR(VLOOKUP($H34,PQ_Diario!$A:$D,4,0),"")) | S34: 0.01629 | T34: 0.01712 | U34: 0.01711
A35: 45809 | B35: =IFERROR(VLOOKUP($A35,PQ_Mensual!$A:$D,2,0),S35) | C35: =IFERROR(VLOOKUP($A35,PQ_Mensual!$A:$D,3,0),T35) | D35: =IFERROR(VLOOKUP($A35,PQ_Mensual!$A:$D,4,0),U35) | E35: =IF(COUNT(B35:D35)=0,"",AVERAGE(B35:D35)) | F35: =IF(E35="","",E35*1000) | H35: =IF(30>DAY(EOMONTH($I$3,0)),"",DATE(YEAR($I$3),MONTH($I$3),30)) | I35: =IF($H35="","",IFERROR(VLOOKUP($H35,PQ_Diario!$A:$D,2,0),"")) | J35: =IF($H35="","",IFERROR(VLOOKUP($H35,PQ_Diario!$A:$D,3,0),"")) | K35: =IF($H35="","",IFERROR(VLOOKUP($H35,PQ_Diario!$A:$D,4,0),"")) | S35: 0.07062 | T35: 0.06936 | U35: 0.07488
A36: 45839 | B36: =IFERROR(VLOOKUP($A36,PQ_Mensual!$A:$D,2,0),S36) | C36: =IFERROR(VLOOKUP($A36,PQ_Mensual!$A:$D,3,0),T36) | D36: =IFERROR(VLOOKUP($A36,PQ_Mensual!$A:$D,4,0),U36) | E36: =IF(COUNT(B36:D36)=0,"",AVERAGE(B36:D36)) | F36: =IF(E36="","",E36*1000) | H36: =IF(31>DAY(EOMONTH($I$3,0)),"",DATE(YEAR($I$3),MONTH($I$3),31)) | I36: =IF($H36="","",IFERROR(VLOOKUP($H36,PQ_Diario!$A:$D,2,0),"")) | J36: =IF($H36="","",IFERROR(VLOOKUP($H36,PQ_Diario!$A:$D,3,0),"")) | K36: =IF($H36="","",IFERROR(VLOOKUP($H36,PQ_Diario!$A:$D,4,0),"")) | S36: 0.06641 | T36: 0.06963 | U36: 0.07197
A37: 45870 | B37: =IFERROR(VLOOKUP($A37,PQ_Mensual!$A:$D,2,0),S37) | C37: =IFERROR(VLOOKUP($A37,PQ_Mensual!$A:$D,3,0),T37) | D37: =IFERROR(VLOOKUP($A37,PQ_Mensual!$A:$D,4,0),U37) | E37: =IF(COUNT(B37:D37)=0,"",AVERAGE(B37:D37)) | F37: =IF(E37="","",E37*1000) | H37: 1ª quincena | I37: =IFERROR(AVERAGE(I6:I20),0) | J37: =IFERROR(AVERAGE(J6:J20),0) | K37: =IFERROR(AVERAGE(K6:K20),0) | S37: 0.06575 | T37: 0.06478 | U37: 0.07084
A38: 45901 | B38: =IFERROR(VLOOKUP($A38,PQ_Mensual!$A:$D,2,0),S38) | C38: =IFERROR(VLOOKUP($A38,PQ_Mensual!$A:$D,3,0),T38) | D38: =IFERROR(VLOOKUP($A38,PQ_Mensual!$A:$D,4,0),U38) | E38: =IF(COUNT(B38:D38)=0,"",AVERAGE(B38:D38)) | F38: =IF(E38="","",E38*1000) | H38: 2ª quincena | I38: =IFERROR(AVERAGE(I21:I36),0) | J38: =IFERROR(AVERAGE(J21:J36),0) | K38: =IFERROR(AVERAGE(K21:K36),0) | S38: 0.06124 | T38: 0.05401 | U38: 0.06431
A39: 45931 | B39: =IFERROR(VLOOKUP($A39,PQ_Mensual!$A:$D,2,0),S39) | C39: =IFERROR(VLOOKUP($A39,PQ_Mensual!$A:$D,3,0),T39) | D39: =IFERROR(VLOOKUP($A39,PQ_Mensual!$A:$D,4,0),U39) | E39: =IF(COUNT(B39:D39)=0,"",AVERAGE(B39:D39)) | F39: =IF(E39="","",E39*1000) | H39: MEDIA MES | I39: =IFERROR(AVERAGE(I6:I36),0) | J39: =IFERROR(AVERAGE(J6:J36),0) | K39: =IFERROR(AVERAGE(K6:K36),0) | S39: 0.08476 | T39: 0.0762 | U39: 0.07113
A40: 45962 | B40: =IFERROR(VLOOKUP($A40,PQ_Mensual!$A:$D,2,0),S40) | C40: =IFERROR(VLOOKUP($A40,PQ_Mensual!$A:$D,3,0),T40) | D40: =IFERROR(VLOOKUP($A40,PQ_Mensual!$A:$D,4,0),U40) | E40: =IF(COUNT(B40:D40)=0,"",AVERAGE(B40:D40)) | F40: =IF(E40="","",E40*1000) | H40: vs media últimos 12 meses cerrados | J40: =IFERROR(J39/AVERAGEIF(F6:F65,">0")-1,0) | S40: 0.06549 | T40: 0.06259 | U40: 0.05434
...

Sheet OMIE_6P
A1: OMIE — SPOT 3.0TD / 6.1TD: mensual por periodo P1…P6 (con temporadas)
A2: Mismo spot OMIE clasificado con el calendario 6 periodos (Circular 3/2020): cada mes solo cotiza los DOS periodos de su temporada + P6 (0-8h laborables, findes y festivos). Temporadas: ALTA ene/feb/jul/dic (P1-P2) · MEDIA-ALTA mar/nov (P2-P3) · MEDIA jun/ago/sep (P3-P4) · BAJA abr/may/oct (P4-P5). Las celdas grises no cotizan ese mes. Base para valorar indexados 3.0/6.1 (pool + fee) y la jugada de cierres trimestrales.
A4: UMBRAL de color (€/MWh) → | H4: 110
A5: Mes | B5: P1 | C5: P2 | D5: P3 | E5: P4 | F5: P5 | G5: P6 | H5: Media (€/MWh) | I5: Temporada
A6: 44927 | B6: =IFERROR(VLOOKUP($A6,PQ_Mensual6P!$A:$G,2,0),S6) | C6: =IFERROR(VLOOKUP($A6,PQ_Mensual6P!$A:$G,3,0),T6) | G6: =IFERROR(VLOOKUP($A6,PQ_Mensual6P!$A:$G,7,0),X6) | H6: =IF(COUNT(B6:G6)=0,"",AVERAGE(B6:G6)*1000) | I6: ALTA | S6: 0.10279 | T6: 0.08306 | X6: 0.04928
A7: 44958 | B7: =IFERROR(VLOOKUP($A7,PQ_Mensual6P!$A:$G,2,0),S7) | C7: =IFERROR(VLOOKUP($A7,PQ_Mensual6P!$A:$G,3,0),T7) | G7: =IFERROR(VLOOKUP($A7,PQ_Mensual6P!$A:$G,7,0),X7) | H7: =IF(COUNT(B7:G7)=0,"",AVERAGE(B7:G7)*1000) | I7: ALTA | S7: 0.14911 | T7: 0.13941 | X7: 0.12311
A8: 44986 | C8: =IFERROR(VLOOKUP($A8,PQ_Mensual6P!$A:$G,3,0),T8) | D8: =IFERROR(VLOOKUP($A8,PQ_Mensual6P!$A:$G,4,0),U8) | G8: =IFERROR(VLOOKUP($A8,PQ_Mensual6P!$A:$G,7,0),X8) | H8: =IF(COUNT(B8:G8)=0,"",AVERAGE(B8:G8)*1000) | I8: M-ALTA | T8: 0.09642 | U8: 0.08468 | X8: 0.08814
A9: 45017 | E9: =IFERROR(VLOOKUP($A9,PQ_Mensual6P!$A:$G,5,0),V9) | F9: =IFERROR(VLOOKUP($A9,PQ_Mensual6P!$A:$G,6,0),W9) | G9: =IFERROR(VLOOKUP($A9,PQ_Mensual6P!$A:$G,7,0),X9) | H9: =IF(COUNT(B9:G9)=0,"",AVERAGE(B9:G9)*1000) | I9: BAJA | V9: 0.0816 | W9: 0.07113 | X9: 0.0711
A10: 45047 | E10: =IFERROR(VLOOKUP($A10,PQ_Mensual6P!$A:$G,5,0),V10) | F10: =IFERROR(VLOOKUP($A10,PQ_Mensual6P!$A:$G,6,0),W10) | G10: =IFERROR(VLOOKUP($A10,PQ_Mensual6P!$A:$G,7,0),X10) | H10: =IF(COUNT(B10:G10)=0,"",AVERAGE(B10:G10)*1000) | I10: BAJA | V10: 0.07783 | W10: 0.07274 | X10: 0.07295
A11: 45078 | D11: =IFERROR(VLOOKUP($A11,PQ_Mensual6P!$A:$G,4,0),U11) | E11: =IFERROR(VLOOKUP($A11,PQ_Mensual6P!$A:$G,5,0),V11) | G11: =IFERROR(VLOOKUP($A11,PQ_Mensual6P!$A:$G,7,0),X11) | H11: =IF(COUNT(B11:G11)=0,"",AVERAGE(B11:G11)*1000) | I11: MEDIA | U11: 0.09868 | V11: 0.09654 | X11: 0.08851
A12: 45108 | B12: =IFERROR(VLOOKUP($A12,PQ_Mensual6P!$A:$G,2,0),S12) | C12: =IFERROR(VLOOKUP($A12,PQ_Mensual6P!$A:$G,3,0),T12) | G12: =IFERROR(VLOOKUP($A12,PQ_Mensual6P!$A:$G,7,0),X12) | H12: =IF(COUNT(B12:G12)=0,"",AVERAGE(B12:G12)*1000) | I12: ALTA | S12: 0.099 | T12: 0.09657 | X12: 0.08432
A13: 45139 | D13: =IFERROR(VLOOKUP($A13,PQ_Mensual6P!$A:$G,4,0),U13) | E13: =IFERROR(VLOOKUP($A13,PQ_Mensual6P!$A:$G,5,0),V13) | G13: =IFERROR(VLOOKUP($A13,PQ_Mensual6P!$A:$G,7,0),X13) | H13: =IF(COUNT(B13:G13)=0,"",AVERAGE(B13:G13)*1000) | I13: MEDIA | U13: 0.10185 | V13: 0.09733 | X13: 0.09261
A14: 45170 | D14: =IFERROR(VLOOKUP($A14,PQ_Mensual6P!$A:$G,4,0),U14) | E14: =IFERROR(VLOOKUP($A14,PQ_Mensual6P!$A:$G,5,0),V14) | G14: =IFERROR(VLOOKUP($A14,PQ_Mensual6P!$A:$G,7,0),X14) | H14: =IF(COUNT(B14:G14)=0,"",AVERAGE(B14:G14)*1000) | I14: MEDIA | U14: 0.11303 | V14: 0.10356 | X14: 0.09848
A15: 45200 | E15: =IFERROR(VLOOKUP($A15,PQ_Mensual6P!$A:$G,5,0),V15) | F15: =IFERROR(VLOOKUP($A15,PQ_Mensual6P!$A:$G,6,0),W15) | G15: =IFERROR(VLOOKUP($A15,PQ_Mensual6P!$A:$G,7,0),X15) | H15: =IF(COUNT(B15:G15)=0,"",AVERAGE(B15:G15)*1000) | I15: BAJA | V15: 0.10093 | W15: 0.08884 | X15: 0.08542
A16: 45231 | C16: =IFERROR(VLOOKUP($A16,PQ_Mensual6P!$A:$G,3,0),T16) | D16: =IFERROR(VLOOKUP($A16,PQ_Mensual6P!$A:$G,4,0),U16) | G16: =IFERROR(VLOOKUP($A16,PQ_Mensual6P!$A:$G,7,0),X16) | H16: =IF(COUNT(B16:G16)=0,"",AVERAGE(B16:G16)*1000) | I16: M-ALTA | T16: 0.07967 | U16: 0.07312 | X16: 0.05176
A17: 45261 | B17: =IFERROR(VLOOKUP($A17,PQ_Mensual6P!$A:$G,2,0),S17) | C17: =IFERROR(VLOOKUP($A17,PQ_Mensual6P!$A:$G,3,0),T17) | G17: =IFERROR(VLOOKUP($A17,PQ_Mensual6P!$A:$G,7,0),X17) | H17: =IF(COUNT(B17:G17)=0,"",AVERAGE(B17:G17)*1000) | I17: ALTA | S17: 0.08833 | T17: 0.08225 | X17: 0.06365
A18: 45292 | B18: =IFERROR(VLOOKUP($A18,PQ_Mensual6P!$A:$G,2,0),S18) | C18: =IFERROR(VLOOKUP($A18,PQ_Mensual6P!$A:$G,3,0),T18) | G18: =IFERROR(VLOOKUP($A18,PQ_Mensual6P!$A:$G,7,0),X18) | H18: =IF(COUNT(B18:G18)=0,"",AVERAGE(B18:G18)*1000) | I18: ALTA | S18: 0.08869 | T18: 0.08048 | X18: 0.06423
A19: 45323 | B19: =IFERROR(VLOOKUP($A19,PQ_Mensual6P!$A:$G,2,0),S19) | C19: =IFERROR(VLOOKUP($A19,PQ_Mensual6P!$A:$G,3,0),T19) | G19: =IFERROR(VLOOKUP($A19,PQ_Mensual6P!$A:$G,7,0),X19) | H19: =IF(COUNT(B19:G19)=0,"",AVERAGE(B19:G19)*1000) | I19: ALTA | S19: 0.04734 | T19: 0.03985 | X19: 0.03621
A20: 45352 | C20: =IFERROR(VLOOKUP($A20,PQ_Mensual6P!$A:$G,3,0),T20) | D20: =IFERROR(VLOOKUP($A20,PQ_Mensual6P!$A:$G,4,0),U20) | G20: =IFERROR(VLOOKUP($A20,PQ_Mensual6P!$A:$G,7,0),X20) | H20: =IF(COUNT(B20:G20)=0,"",AVERAGE(B20:G20)*1000) | I20: M-ALTA | T20: 0.02995 | U20: 0.02173 | X20: 0.01531
A21: 45383 | E21: =IFERROR(VLOOKUP($A21,PQ_Mensual6P!$A:$G,5,0),V21) | F21: =IFERROR(VLOOKUP($A21,PQ_Mensual6P!$A:$G,6,0),W21) | G21: =IFERROR(VLOOKUP($A21,PQ_Mensual6P!$A:$G,7,0),X21) | H21: =IF(COUNT(B21:G21)=0,"",AVERAGE(B21:G21)*1000) | I21: BAJA | V21: 0.014 | W21: 0.01397 | X21: 0.01337
A22: 45413 | E22: =IFERROR(VLOOKUP($A22,PQ_Mensual6P!$A:$G,5,0),V22) | F22: =IFERROR(VLOOKUP($A22,PQ_Mensual6P!$A:$G,6,0),W22) | G22: =IFERROR(VLOOKUP($A22,PQ_Mensual6P!$A:$G,7,0),X22) | H22: =IF(COUNT(B22:G22)=0,"",AVERAGE(B22:G22)*1000) | I22: BAJA | V22: 0.02739 | W22: 0.0275 | X22: 0.03306
A23: 45444 | D23: =IFERROR(VLOOKUP($A23,PQ_Mensual6P!$A:$G,4,0),U23) | E23: =IFERROR(VLOOKUP($A23,PQ_Mensual6P!$A:$G,5,0),V23) | G23: =IFERROR(VLOOKUP($A23,PQ_Mensual6P!$A:$G,7,0),X23) | H23: =IF(COUNT(B23:G23)=0,"",AVERAGE(B23:G23)*1000) | I23: MEDIA | U23: 0.06281 | V23: 0.0594 | X23: 0.05189
A24: 45474 | B24: =IFERROR(VLOOKUP($A24,PQ_Mensual6P!$A:$G,2,0),S24) | C24: =IFERROR(VLOOKUP($A24,PQ_Mensual6P!$A:$G,3,0),T24) | G24: =IFERROR(VLOOKUP($A24,PQ_Mensual6P!$A:$G,7,0),X24) | H24: =IF(COUNT(B24:G24)=0,"",AVERAGE(B24:G24)*1000) | I24: ALTA | S24: 0.07517 | T24: 0.073 | X24: 0.07045
A25: 45505 | D25: =IFERROR(VLOOKUP($A25,PQ_Mensual6P!$A:$G,4,0),U25) | E25: =IFERROR(VLOOKUP($A25,PQ_Mensual6P!$A:$G,5,0),V25) | G25: =IFERROR(VLOOKUP($A25,PQ_Mensual6P!$A:$G,7,0),X25) | H25: =IF(COUNT(B25:G25)=0,"",AVERAGE(B25:G25)*1000) | I25: MEDIA | U25: 0.0989 | V25: 0.09615 | X25: 0.08558
A26: 45536 | D26: =IFERROR(VLOOKUP($A26,PQ_Mensual6P!$A:$G,4,0),U26) | E26: =IFERROR(VLOOKUP($A26,PQ_Mensual6P!$A:$G,5,0),V26) | G26: =IFERROR(VLOOKUP($A26,PQ_Mensual6P!$A:$G,7,0),X26) | H26: =IF(COUNT(B26:G26)=0,"",AVERAGE(B26:G26)*1000) | I26: MEDIA | U26: 0.07846 | V26: 0.06545 | X26: 0.0725
A27: 45566 | E27: =IFERROR(VLOOKUP($A27,PQ_Mensual6P!$A:$G,5,0),V27) | F27: =IFERROR(VLOOKUP($A27,PQ_Mensual6P!$A:$G,6,0),W27) | G27: =IFERROR(VLOOKUP($A27,PQ_Mensual6P!$A:$G,7,0),X27) | H27: =IF(COUNT(B27:G27)=0,"",AVERAGE(B27:G27)*1000) | I27: BAJA | V27: 0.08416 | W27: 0.06969 | X27: 0.0595
A28: 45597 | C28: =IFERROR(VLOOKUP($A28,PQ_Mensual6P!$A:$G,3,0),T28) | D28: =IFERROR(VLOOKUP($A28,PQ_Mensual6P!$A:$G,4,0),U28) | G28: =IFERROR(VLOOKUP($A28,PQ_Mensual6P!$A:$G,7,0),X28) | H28: =IF(COUNT(B28:G28)=0,"",AVERAGE(B28:G28)*1000) | I28: M-ALTA | T28: 0.11873 | U28: 0.11559 | X28: 0.09409
A29: 45627 | B29: =IFERROR(VLOOKUP($A29,PQ_Mensual6P!$A:$G,2,0),S29) | C29: =IFERROR(VLOOKUP($A29,PQ_Mensual6P!$A:$G,3,0),T29) | G29: =IFERROR(VLOOKUP($A29,PQ_Mensual6P!$A:$G,7,0),X29) | H29: =IF(COUNT(B29:G29)=0,"",AVERAGE(B29:G29)*1000) | I29: ALTA | S29: 0.12771 | T29: 0.12394 | X29: 0.10005
A30: 45658 | B30: =IFERROR(VLOOKUP($A30,PQ_Mensual6P!$A:$G,2,0),S30) | C30: =IFERROR(VLOOKUP($A30,PQ_Mensual6P!$A:$G,3,0),T30) | G30: =IFERROR(VLOOKUP($A30,PQ_Mensual6P!$A:$G,7,0),X30) | H30: =IF(COUNT(B30:G30)=0,"",AVERAGE(B30:G30)*1000) | I30: ALTA | S30: 0.11677 | T30: 0.10875 | X30: 0.08304
A31: 45689 | B31: =IFERROR(VLOOKUP($A31,PQ_Mensual6P!$A:$G,2,0),S31) | C31: =IFERROR(VLOOKUP($A31,PQ_Mensual6P!$A:$G,3,0),T31) | G31: =IFERROR(VLOOKUP($A31,PQ_Mensual6P!$A:$G,7,0),X31) | H31: =IF(COUNT(B31:G31)=0,"",AVERAGE(B31:G31)*1000) | I31: ALTA | S31: 0.12383 | T31: 0.10691 | X31: 0.10093
A32: 45717 | C32: =IFERROR(VLOOKUP($A32,PQ_Mensual6P!$A:$G,3,0),T32) | D32: =IFERROR(VLOOKUP($A32,PQ_Mensual6P!$A:$G,4,0),U32) | G32: =IFERROR(VLOOKUP($A32,PQ_Mensual6P!$A:$G,7,0),X32) | H32: =IF(COUNT(B32:G32)=0,"",AVERAGE(B32:G32)*1000) | I32: M-ALTA | T32: 0.06889 | U32: 0.05535 | X32: 0.04494
A33: 45748 | E33: =IFERROR(VLOOKUP($A33,PQ_Mensual6P!$A:$G,5,0),V33) | F33: =IFERROR(VLOOKUP($A33,PQ_Mensual6P!$A:$G,6,0),W33) | G33: =IFERROR(VLOOKUP($A33,PQ_Mensual6P!$A:$G,7,0),X33) | H33: =IF(COUNT(B33:G33)=0,"",AVERAGE(B33:G33)*1000) | I33: BAJA | V33: 0.02742 | W33: 0.02611 | X33: 0.02677
A34: 45778 | E34: =IFERROR(VLOOKUP($A34,PQ_Mensual6P!$A:$G,5,0),V34) | F34: =IFERROR(VLOOKUP($A34,PQ_Mensual6P!$A:$G,6,0),W34) | G34: =IFERROR(VLOOKUP($A34,PQ_Mensual6P!$A:$G,7,0),X34) | H34: =IF(COUNT(B34:G34)=0,"",AVERAGE(B34:G34)*1000) | I34: BAJA | V34: 0.01571 | W34: 0.01798 | X34: 0.01711
A35: 45809 | D35: =IFERROR(VLOOKUP($A35,PQ_Mensual6P!$A:$G,4,0),U35) | E35: =IFERROR(VLOOKUP($A35,PQ_Mensual6P!$A:$G,5,0),V35) | G35: =IFERROR(VLOOKUP($A35,PQ_Mensual6P!$A:$G,7,0),X35) | H35: =IF(COUNT(B35:G35)=0,"",AVERAGE(B35:G35)*1000) | I35: MEDIA | U35: 0.07118 | V35: 0.06846 | X35: 0.07488
A36: 45839 | B36: =IFERROR(VLOOKUP($A36,PQ_Mensual6P!$A:$G,2,0),S36) | C36: =IFERROR(VLOOKUP($A36,PQ_Mensual6P!$A:$G,3,0),T36) | G36: =IFERROR(VLOOKUP($A36,PQ_Mensual6P!$A:$G,7,0),X36) | H36: =IF(COUNT(B36:G36)=0,"",AVERAGE(B36:G36)*1000) | I36: ALTA | S36: 0.06657 | T36: 0.06987 | X36: 0.07197
A37: 45870 | D37: =IFERROR(VLOOKUP($A37,PQ_Mensual6P!$A:$G,4,0),U37) | E37: =IFERROR(VLOOKUP($A37,PQ_Mensual6P!$A:$G,5,0),V37) | G37: =IFERROR(VLOOKUP($A37,PQ_Mensual6P!$A:$G,7,0),X37) | H37: =IF(COUNT(B37:G37)=0,"",AVERAGE(B37:G37)*1000) | I37: MEDIA | U37: 0.0668 | V37: 0.06331 | X37: 0.07084
A38: 45901 | D38: =IFERROR(VLOOKUP($A38,PQ_Mensual6P!$A:$G,4,0),U38) | E38: =IFERROR(VLOOKUP($A38,PQ_Mensual6P!$A:$G,5,0),V38) | G38: =IFERROR(VLOOKUP($A38,PQ_Mensual6P!$A:$G,7,0),X38) | H38: =IF(COUNT(B38:G38)=0,"",AVERAGE(B38:G38)*1000) | I38: MEDIA | U38: 0.06231 | V38: 0.0516 | X38: 0.06431
A39: 45931 | E39: =IFERROR(VLOOKUP($A39,PQ_Mensual6P!$A:$G,5,0),V39) | F39: =IFERROR(VLOOKUP($A39,PQ_Mensual6P!$A:$G,6,0),W39) | G39: =IFERROR(VLOOKUP($A39,PQ_Mensual6P!$A:$G,7,0),X39) | H39: =IF(COUNT(B39:G39)=0,"",AVERAGE(B39:G39)*1000) | I39: BAJA | V39: 0.08625 | W39: 0.07305 | X39: 0.07113
A40: 45962 | C40: =IFERROR(VLOOKUP($A40,PQ_Mensual6P!$A:$G,3,0),T40) | D40: =IFERROR(VLOOKUP($A40,PQ_Mensual6P!$A:$G,4,0),U40) | G40: =IFERROR(VLOOKUP($A40,PQ_Mensual6P!$A:$G,7,0),X40) | H40: =IF(COUNT(B40:G40)=0,"",AVERAGE(B40:G40)*1000) | I40: M-ALTA | T40: 0.06467 | U40: 0.06322 | X40: 0.05434
A41: 45992 | B41: =IFERROR(VLOOKUP($A41,PQ_Mensual6P!$A:$G,2,0),S41) | C41: =IFERROR(VLOOKUP($A41,PQ_Mensual6P!$A:$G,3,0),T41) | G41: =IFERROR(VLOOKUP($A41,PQ_Mensual6P!$A:$G,7,0),X41) | H41: =IF(COUNT(B41:G41)=0,"",AVERAGE(B41:G41)*1000) | I41: ALTA | S41: 0.09152 | T41: 0.08801 | X41: 0.06796
...

Sheet OMIP
A1: OMIP — FUTUROS ELÉCTRICOS ESPAÑA (FTB): curva forward + ventana de fijación
A2: El parabrisas: lo que el mercado paga HOY por la electricidad de mañana. Los fijos de las comercializadoras se construyen sobre esta curva (forward + peajes/ajustes + cobertura + fee), así que se mueve ANTES que el spot: es el indicador adelantado del radar. Con la consulta PQ_OMIP se actualiza sola; si no, teclea la columna Manual (amarilla, 5 min/semana desde omip.pt).
A4: Fecha de la lectura: | C4: 46245 | D4: (con PQ_OMIP cargado, la lectura es la del último refresco)
A5: Clave | B5: Instrumento | C5: Precio (€/MWh) | D5: Manual | E5: Peso forward (meses) | G5: CÓMO SE LEE LA CURVA:
A6: M1 | B6: =IFERROR(VLOOKUP($A6,PQ_OMIP!$A:$C,2,0),J6) | C6: =IFERROR(VLOOKUP($A6,PQ_OMIP!$A:$C,3,0),D6) | D6: 115.75 | E6: 1 | G6: · Corto tenso: Sep-Dic 26 cotizan 97-103 €/MWh. | J6: FTB M Sep-26
A7: M2 | B7: =IFERROR(VLOOKUP($A7,PQ_OMIP!$A:$C,2,0),J7) | C7: =IFERROR(VLOOKUP($A7,PQ_OMIP!$A:$C,3,0),D7) | D7: 107.5 | E7: 0 | G7: · Q2-27 a 45,85: el mercado espera primaveras hundidas (solar). Es la base de la jugada trimestral: cerrar Q1/Q3 y dejar Q2 indexado. | J7: FTB M Oct-26
A8: M3 | B8: =IFERROR(VLOOKUP($A8,PQ_OMIP!$A:$C,2,0),J8) | C8: =IFERROR(VLOOKUP($A8,PQ_OMIP!$A:$C,3,0),D8) | D8: 111.91 | E8: 0 | G8: · Curva anual bajista: YR-27 66 → YR-29 53. El mercado espera normalización: cuidado con fijar 2-3 años a precios de hoy. | J8: FTB M Nov-26
A9: M4 | B9: =IFERROR(VLOOKUP($A9,PQ_OMIP!$A:$C,2,0),J9) | C9: =IFERROR(VLOOKUP($A9,PQ_OMIP!$A:$C,3,0),D9) | D9: 112.88 | E9: 0 | G9: · Pesos del forward: 12 meses contiguos (por defecto Sep+Oct+Nov+Dic + Q1-27×3 + Q2-27×3 + Q3-27×2). Cuando cambie el mes, reajusta pesos. | J9: FTB M Dec-26
A10: M5 | B10: =IFERROR(VLOOKUP($A10,PQ_OMIP!$A:$C,2,0),J10) | C10: =IFERROR(VLOOKUP($A10,PQ_OMIP!$A:$C,3,0),D10) | D10: 98.56 | E10: 0 | G10: · Fórmula sectorial del fijo (validada al euro): forward + ~28 peajes/ajustes + ~10 cobertura + fee. | J10: FTB M Jan-27
A11: M6 | B11: =IFERROR(VLOOKUP($A11,PQ_OMIP!$A:$C,2,0),J11) | C11: =IFERROR(VLOOKUP($A11,PQ_OMIP!$A:$C,3,0),D11) | D11: 93.4 | E11: 0 | J11: FTB M Feb-27
A12: Q1 | B12: =IFERROR(VLOOKUP($A12,PQ_OMIP!$A:$C,2,0),J12) | C12: =IFERROR(VLOOKUP($A12,PQ_OMIP!$A:$C,3,0),D12) | D12: 110.75 | E12: 3 | J12: FTB Q4-26
A13: Q2 | B13: =IFERROR(VLOOKUP($A13,PQ_OMIP!$A:$C,2,0),J13) | C13: =IFERROR(VLOOKUP($A13,PQ_OMIP!$A:$C,3,0),D13) | D13: 92 | E13: 3 | J13: FTB Q1-27
A14: Q3 | B14: =IFERROR(VLOOKUP($A14,PQ_OMIP!$A:$C,2,0),J14) | C14: =IFERROR(VLOOKUP($A14,PQ_OMIP!$A:$C,3,0),D14) | D14: 46.39 | E14: 3 | J14: FTB Q2-27
A15: Q4 | B15: =IFERROR(VLOOKUP($A15,PQ_OMIP!$A:$C,2,0),J15) | C15: =IFERROR(VLOOKUP($A15,PQ_OMIP!$A:$C,3,0),D15) | D15: 71.4 | E15: 2 | J15: FTB Q3-27
A16: Q5 | B16: =IFERROR(VLOOKUP($A16,PQ_OMIP!$A:$C,2,0),J16) | C16: =IFERROR(VLOOKUP($A16,PQ_OMIP!$A:$C,3,0),D16) | D16: 70.44 | E16: 0 | J16: FTB Q4-27
A17: Q6 | B17: =IFERROR(VLOOKUP($A17,PQ_OMIP!$A:$C,2,0),J17) | C17: =IFERROR(VLOOKUP($A17,PQ_OMIP!$A:$C,3,0),D17) | D17: 64.61 | E17: 0 | J17: FTB Q1-28
A18: Q7 | B18: =IFERROR(VLOOKUP($A18,PQ_OMIP!$A:$C,2,0),J18) | C18: =IFERROR(VLOOKUP($A18,PQ_OMIP!$A:$C,3,0),D18) | D18: 41.55 | E18: 0 | J18: FTB Q2-28
A19: Y1 | B19: =IFERROR(VLOOKUP($A19,PQ_OMIP!$A:$C,2,0),J19) | C19: =IFERROR(VLOOKUP($A19,PQ_OMIP!$A:$C,3,0),D19) | D19: 70 | E19: 0 | J19: FTB YR-27
A20: Y2 | B20: =IFERROR(VLOOKUP($A20,PQ_OMIP!$A:$C,2,0),J20) | C20: =IFERROR(VLOOKUP($A20,PQ_OMIP!$A:$C,3,0),D20) | D20: 57.5 | E20: 0 | J20: FTB YR-28
A21: Y3 | B21: =IFERROR(VLOOKUP($A21,PQ_OMIP!$A:$C,2,0),J21) | C21: =IFERROR(VLOOKUP($A21,PQ_OMIP!$A:$C,3,0),D21) | D21: 53.22 | E21: 0 | J21: FTB YR-29
A23: Suma de pesos (debe ser 12) | C23: =SUM(E6:E21) | D23: =IF(C23=12,"OK","⚠ ajusta pesos")
A24: FORWARD PRÓXIMOS 12 MESES (€/MWh) | C24: =SUMPRODUCT(C6:C21,E6:E21)/SUM(E6:E21)
A25: Peajes y ajustes (€/MWh) | C25: 28
A26: Cobertura de seguridad (€/MWh) | C26: 10
A27: Precio fijo TEÓRICO hoy (€/MWh) | C27: =C24+C25+C26
A28: Mejor fijo del catálogo — energía (€/MWh) | C28: 109.9
A29: VENTANA DE FIJACIÓN (teórico − catálogo) | C29: =C27-C28
A30: =IF(C29>5,"VENTANA ABIERTA: quien fija hoy compra por debajo de donde repreciará el catálogo",IF(C29<-5,"El catálogo está caro frente al mercado: negociar o esperar","Neutral: catálogo alineado con el mercado"))

Sheet PQ_Mensual
A1: Zona de carga Power Query — consulta 'Mensual'. Cargar la tabla en A1. Vacía de fábrica: el panel usa los congelados.

Sheet PQ_Diario
A1: Zona de carga Power Query — consulta 'Diario'. Cargar la tabla en A1. Vacía de fábrica: el panel usa los congelados.

Sheet PQ_Mensual6P
A1: Zona de carga Power Query — consulta 'OMIE_Mensual6P'. Cargar la tabla en A1. Vacía de fábrica: el panel usa los congelados.

Sheet PQ_OMIP
A1: Zona de carga Power Query — consulta 'OMIP'. Cargar la tabla en A1. Vacía de fábrica: el panel usa los congelados.
